<?xml version="1.0"?>
<robot name="warehouse_amr" xmlns:xacro="http://www.ros.org/wiki/xacro">

  <xacro:property name="base_length"   value="0.6"/>
  <xacro:property name="base_width"    value="0.4"/>
  <xacro:property name="base_height"   value="0.15"/>
  <xacro:property name="base_mass"     value="20.0"/>
  <xacro:property name="wheel_radius"  value="0.1"/>
  <xacro:property name="wheel_width"   value="0.05"/>
  <xacro:property name="wheel_mass"    value="1.0"/>
  <xacro:property name="wheel_x_off"   value="0.2"/>
  <xacro:property name="wheel_y_off"   value="0.225"/>
  <xacro:property name="wheel_z_off"   value="${-base_height/2}"/>

  <xacro:macro name="box_inertia" params="m l w h">
    <inertial>
      <mass value="${m}"/>
      <inertia ixx="${m*(w*w+h*h)/12}" ixy="0" ixz="0"
               iyy="${m*(l*l+h*h)/12}" iyz="0"
               izz="${m*(l*l+w*w)/12}"/>
    </inertial>
  </xacro:macro>

  <xacro:macro name="cylinder_inertia" params="m r h">
    <inertial>
      <mass value="${m}"/>
      <inertia ixx="${m*(3*r*r+h*h)/12}" ixy="0" ixz="0"
               iyy="${m*(3*r*r+h*h)/12}" iyz="0"
               izz="${m*r*r/2}"/>
    </inertial>
  </xacro:macro>

  <xacro:macro name="wheel" params="name side pos">
    <link name="${name}_wheel">
      <visual>
        <geometry><cylinder radius="${wheel_radius}" length="${wheel_width}"/></geometry>
        <origin xyz="0 0 0" rpy="${pi/2} 0 0"/>
        <material name="dark_grey"><color rgba="0.2 0.2 0.2 1"/></material>
      </visual>
      <collision>
        <geometry><cylinder radius="${wheel_radius}" length="${wheel_width}"/></geometry>
        <origin xyz="0 0 0" rpy="${pi/2} 0 0"/>
      </collision>
      <xacro:cylinder_inertia m="${wheel_mass}" r="${wheel_radius}" h="${wheel_width}"/>
    </link>
    <joint name="${name}_wheel_joint" type="continuous">
      <parent link="base_link"/>
      <child  link="${name}_wheel"/>
      <origin xyz="${pos*wheel_x_off} ${side*wheel_y_off} ${wheel_z_off}" rpy="0 0 0"/>
      <axis xyz="0 1 0"/>
      <dynamics damping="0.1" friction="0.5"/>
    </joint>
  </xacro:macro>

  <link name="base_footprint"/>
  <joint name="base_footprint_joint" type="fixed">
    <parent link="base_footprint"/>
    <child  link="base_link"/>
    <origin xyz="0 0 ${wheel_radius}" rpy="0 0 0"/>
  </joint>

  <link name="base_link">
    <visual>
      <geometry><box size="${base_length} ${base_width} ${base_height}"/></geometry>
      <origin xyz="0 0 0" rpy="0 0 0"/>
      <material name="orange"><color rgba="1.0 0.5 0.0 1"/></material>
    </visual>
    <collision>
      <geometry><box size="${base_length} ${base_width} ${base_height}"/></geometry>
      <origin xyz="0 0 0" rpy="0 0 0"/>
    </collision>
    <xacro:box_inertia m="${base_mass}" l="${base_length}" w="${base_width}" h="${base_height}"/>
  </link>

  <xacro:wheel name="front_left"  side=" 1" pos=" 1"/>
  <xacro:wheel name="front_right" side="-1" pos=" 1"/>
  <xacro:wheel name="rear_left"   side=" 1" pos="-1"/>
  <xacro:wheel name="rear_right"  side="-1" pos="-1"/>

  <link name="lidar_link">
    <visual>
      <geometry><cylinder radius="0.05" length="0.07"/></geometry>
      <material name="black"><color rgba="0.1 0.1 0.1 1"/></material>
    </visual>
  </link>
  <joint name="lidar_joint" type="fixed">
    <parent link="base_link"/>
    <child  link="lidar_link"/>
    <origin xyz="0.2 0 ${base_height/2 + 0.035}" rpy="0 0 0"/>
  </joint>

  <link name="imu_link">
    <visual>
      <geometry><box size="0.03 0.03 0.01"/></geometry>
      <material name="green"><color rgba="0.0 0.8 0.0 1"/></material>
    </visual>
  </link>
  <joint name="imu_joint" type="fixed">
    <parent link="base_link"/>
    <child  link="imu_link"/>
    <origin xyz="0 0 ${base_height/2 + 0.005}" rpy="0 0 0"/>
  </joint>

  <link name="depth_camera_link">
    <visual>
      <geometry><box size="0.05 0.12 0.03"/></geometry>
      <material name="blue"><color rgba="0.0 0.0 0.8 1"/></material>
    </visual>
  </link>
  <joint name="depth_camera_joint" type="fixed">
    <parent link="base_link"/>
    <child  link="depth_camera_link"/>
    <origin xyz="${base_length/2} 0 ${base_height/2 + 0.05}" rpy="0 0 0"/>
  </joint>

  <link name="depth_camera_optical_frame"/>
  <joint name="depth_camera_optical_joint" type="fixed">
    <parent link="depth_camera_link"/>
    <child  link="depth_camera_optical_frame"/>
    <origin xyz="0 0 0" rpy="0 0 0"/>
  </joint>

  <gazebo>
    <plugin filename="ignition-gazebo-diff-drive-system"
            name="ignition::gazebo::systems::DiffDrive">
      <left_joint>front_left_wheel_joint</left_joint>
      <left_joint>rear_left_wheel_joint</left_joint>
      <right_joint>front_right_wheel_joint</right_joint>
      <right_joint>rear_right_wheel_joint</right_joint>
      <wheel_separation>${2*wheel_y_off}</wheel_separation>
      <wheel_radius>${wheel_radius}</wheel_radius>
      <odom_publish_frequency>50</odom_publish_frequency>
      <topic>cmd_vel</topic>
      <odom_topic>odom</odom_topic>
      <frame_id>odom</frame_id>
      <child_frame_id>base_footprint</child_frame_id>
      <tf_topic>/tf</tf_topic>
    </plugin>
    <plugin filename="ignition-gazebo-joint-state-publisher-system"
            name="ignition::gazebo::systems::JointStatePublisher">
      <topic>joint_states</topic>
    </plugin>
    <plugin filename="ignition-gazebo-sensors-system"
            name="ignition::gazebo::systems::Sensors">
      <render_engine>ogre2</render_engine>
    </plugin>
  </gazebo>

  <gazebo reference="lidar_link">
    <sensor name="lidar" type="gpu_lidar">
      <topic>scan</topic>
      <frame_id>lidar_link</frame_id>
      <update_rate>10</update_rate>
      <lidar>
        <scan>
          <horizontal>
            <samples>360</samples>
            <resolution>1</resolution>
            <min_angle>-3.14159</min_angle>
            <max_angle>3.14159</max_angle>
          </horizontal>
        </scan>
        <range>
          <min>0.12</min>
          <max>10.0</max>
          <resolution>0.01</resolution>
        </range>
        <noise><type>gaussian</type><mean>0.0</mean><stddev>0.01</stddev></noise>
      </lidar>
      <always_on>true</always_on>
      <visualize>true</visualize>
    </sensor>
  </gazebo>

  <gazebo reference="imu_link">
    <sensor name="imu_sensor" type="imu">
      <topic>imu/data</topic>
      <update_rate>100</update_rate>
      <imu>
        <angular_velocity>
          <x><noise type="gaussian"><mean>0</mean><stddev>0.009</stddev></noise></x>
          <y><noise type="gaussian"><mean>0</mean><stddev>0.009</stddev></noise></y>
          <z><noise type="gaussian"><mean>0</mean><stddev>0.009</stddev></noise></z>
        </angular_velocity>
        <linear_acceleration>
          <x><noise type="gaussian"><mean>0</mean><stddev>0.021</stddev></noise></x>
          <y><noise type="gaussian"><mean>0</mean><stddev>0.021</stddev></noise></y>
          <z><noise type="gaussian"><mean>0</mean><stddev>0.021</stddev></noise></z>
        </linear_acceleration>
      </imu>
      <always_on>true</always_on>
    </sensor>
  </gazebo>

  <gazebo reference="depth_camera_link">
    <sensor name="depth_camera" type="rgbd_camera">
      <topic>depth_camera</topic>
      <update_rate>30</update_rate>
      <camera>
        <horizontal_fov>1.047</horizontal_fov>
        <image>
          <width>640</width>
          <height>480</height>
          <format>R8G8B8</format>
        </image>
        <clip><near>0.1</near><far>8.0</far></clip>
        <noise><type>gaussian</type><mean>0.0</mean><stddev>0.007</stddev></noise>
      </camera>
      <always_on>true</always_on>
      <visualize>true</visualize>
    </sensor>
  </gazebo>

</robot>
